<?xml version="1.0"?>
<robot xmlns:xacro="http://www.ros.org/wiki/xacro">
<xacro:macro name="ardagv_model" params="name">
        <link name="base_link"></link>

        <link name="chasis">
                <visual>
                        <origin xyz="0 0 0.08" rpy="0 0 0" />
                        <geometry>
                                <box size="0.6 0.3 0.15" />
                        </geometry>
                        <material name="chasis-material">
                                <color rgba="0.5 0.5 0.5 1" />
                        </material>
                </visual>
        </link>
        <joint name="base_to_chasis" type="fixed">
                <parent link="base_link" />
                <child link="chasis" />
        </joint>

        <link name="wheel_left">
                <visual>
                        <origin xyz="0 0 0" rpy="0 0 0" />
                        <geometry>
                                <cylinder radius="0.05" length="0.025" />
                        </geometry>
                        <material name="wheel-material">
                                <color rgba="0.2 0.2 0.2 1" />
                        </material>
                </visual>
        </link>
        <joint name="motor_left" type="continuous">
                <parent link="base_link" />
                <child link="wheel_left" />
                <origin xyz="0 0.1225 0.05" rpy="1.5708 0 0" />
                <command_interface name="velocity"> <!-- RPM limits: -->
                        <param name="min">-18</param>
                        <param name="max">18</param>
                </command_interface>
        </joint>

        <link name="wheel_right">
                <visual>
                        <origin xyz="0 0 0" rpy="0 0 0" />
                        <geometry>
                                <cylinder radius="0.05" length="0.025" />
                        </geometry>
                        <material name="wheel-material">
                                <color rgba="0.2 0.2 0.2 1" />
                        </material>
                </visual>
        </link>
        <joint name="motor_right" type="continuous">
                <parent link="base_link" />
                <child link="wheel_right" />
                <origin xyz="0 -0.1225 0.05" rpy="-1.5708 0 0" />
                <command_interface name="velocity"> <!-- RPM limits: -->
                        <param name="min">-18</param>
                        <param name="max">18</param>
                </command_interface>
        </joint>

        <link name="cam1_adtf31xx">
        </link>
        <joint name="tof_position" type="fixed">
                <parent link="base_link" />
                <!--<child link="cam1_adtf31xx_optical" />
                <origin xyz="0.3 0 0.05" rpy="1.5708 0 1.5708" />-->
                <child link="cam1_adtf31xx" />
                <origin xyz="0.3 0 0.05" rpy="0 0 0" />
        </joint>

        <link name="cam1_laser">
        </link>
        <joint name="laser_position" type="fixed">
                <parent link="base_link" />
                <child link="cam1_laser" />
                <origin xyz="0.3 0 0.05" rpy="0 0 0" />
        </joint>

        <link name="imu">
        </link>
        <joint name="imu_position" type="fixed">
                <parent link="base_link" />
                <child link="imu" />
                <origin xyz="0.133 -0.01 0.05" rpy="1.5708 0 0" />
        </joint>




        <sensor name="tof">
                <parent link="base_link" />
                <origin xyz="0.3 0 0.05" rpy="0 0 0" /> <!-- TODO: orientation -->
                <camera>
                        <image width="512" height="512" hfov="2" format="mono16" near="0.4" far="5" /> <!-- TODO: change FOV, radians -->
                        <image width="512" height="512" hfov="2" format="mono16" near="0.4" far="5" />
                </camera>
        </sensor>

        <sensor name="imu">
                <parent link="base_link" />
                <origin xyz="0.133 -0.01 0.05" rpy="0 0 0" /> <!-- TODO: orientation -->
        </sensor>
</xacro:macro>
</robot>

